<?xml version="1.0"?>
<robot name="guiabot" 
  xmlns:xacro="http://ros.org/wiki/xacro">


<gazebo>
  <plugin name="gazebo_ros_control" filename="libgazebo_ros_control.so">
    <robotNamespace>/guiabot</robotNamespace>
  </plugin>
</gazebo>


<link name="base_link" >

    <visual>  
      <origin xyz="0 0 0.024" rpy="0 0 0"/>
      <geometry>
        <mesh filename="package://guiabot_description/meshes/guaibot.dae" scale="1 1 1"/>
      </geometry>
    </visual>
    <collision>
      <geometry>
        <mesh filename="package://guiabot_description/meshes/guaibot.dae" scale="1 1 1"/>
      </geometry>
    </collision>
  </link>


<link name="left_diff_wheel">
    <inertial>
      <mass value="50"/>
      <!--origin xyz="0 0 -0.0525" rpy="0 0 0"/-->
      <origin rpy="0 0 0" xyz="0 0 0"/>
      <inertia ixx="1" ixy="0" ixz="0" iyy="1" iyz="0" izz="1"/>
    </inertial>
    <visual>
      <origin xyz="0 0 0" rpy="0 0 0"/>
      <geometry>
        <cylinder length="0.008" radius="0.046"/>
      </geometry>
    </visual>
    <collision>
      <origin xyz="0 0 0" rpy="0 0 0"/>
      <geometry>
        <cylinder length="0.008" radius="0.046"/>
      </geometry>
    </collision>
  </link>
 

  <joint name="left_diff_wheel_base"  type="continuous">
    <axis xyz="0 0 -1"/>
    <parent link="base_link"/>
    <child link="left_diff_wheel"/>
    <origin xyz=".295 .095  0.024" rpy="1.5708 0 0"/>
  </joint>
  <gazebo reference="left_diff_wheel">
    <material>Gazebo/Black</material>
    <turnGravityOff>false</turnGravityOff>
  </gazebo>

  <link name="right_diff_wheel">
    <inertial>
      <mass value="50"/>
      <!--origin xyz="0 0 -0.0525" rpy="0 0 0"/-->
      <origin rpy="0 0 0" xyz="0 0 0.0"/>
      <inertia ixx="1" ixy="0" ixz="0" iyy="1" iyz="0" izz="1"/>
    </inertial>
    <visual>
      <origin xyz="0 0 0" rpy="0 0 0"/>
      <geometry>
        <cylinder length="0.008" radius="0.046"/>
      </geometry>
    </visual>
    <collision>
      <origin xyz="0 0 0" rpy="0 0 0"/>
      <geometry>
        <cylinder length="0.008" radius="0.046"/>
      </geometry>
    </collision>
  </link>
  
  <joint name="right_diff_wheel_base"  type="continuous">
    <axis xyz="0 0 -1"/>
   <parent link="base_link"/>
    <child link="right_diff_wheel"/>
    <origin xyz=".295 .395  0.024" rpy="-1.5708 0 0"/>
  </joint>

    <gazebo reference="right_diff_wheel">
    <material>Gazebo/Black</material>
    <turnGravityOff>false</turnGravityOff>
  </gazebo>

  <link name="stabilising_wheel_1">
    <inertial>
      <mass value="1"/>
      <!--origin xyz="0 0 -0.0525" rpy="0 0 0"/-->
      <origin rpy="0 0 0" xyz="0 0 0.0"/>
      <inertia ixx="1" ixy="0" ixz="0" iyy="1" iyz="0" izz="1"/>
    </inertial>
    <visual>
      <origin xyz="0 0 0" rpy="0 0 0"/>
      <geometry>
        <sphere radius="0.020"/>
      </geometry>
    </visual>
    <collision>
      <origin xyz="0 0 0" rpy="0 0 0"/>
      <geometry>
        <sphere radius="0.020"/>
      </geometry>
    </collision>
  </link>
  
  <joint name="stabilising_wheel_base_1" type="continuous">
    <parent link="base_link"/>
    <child link="stabilising_wheel_1"/>
    <origin xyz="0.120 .115 0" rpy="-1.5708 0 0"/>
  </joint>

  <gazebo reference="stabilising_wheel_1">
    <material>Gazebo/Black</material>
    <turnGravityOff>false</turnGravityOff>
  </gazebo>

  <link name="stabilising_wheel_2">
    <inertial>
      <mass value="1"/>
      <!--origin xyz="0 0 -0.0525" rpy="0 0 0"/-->
      <origin rpy="0 0 0" xyz="0 0 0.0"/>
      <inertia ixx="1" ixy="0" ixz="0" iyy="1" iyz="0" izz="1"/>
    </inertial>
    <visual>
      <origin xyz="0 0 0" rpy="0 0 0"/>
      <geometry>
        <sphere radius="0.020"/>
      </geometry>
    </visual>
    <collision>
      <origin xyz="0 0 0" rpy="0 0 0"/>
      <geometry>
        <sphere radius="0.020"/>
      </geometry>
    </collision>
  </link>
  
  <joint name="stabilising_wheel_base_2" type="continuous">
    <axis xyz="1 1 1"/>
    <parent link="base_link"/>
    <child link="stabilising_wheel_2"/>
    <origin xyz="0.120 .365 0" rpy="-1.5708 0 0"/>
  </joint>

  <gazebo reference="stabilising_wheel_2">
    <material>Gazebo/Black</material>
    <turnGravityOff>false</turnGravityOff>
  </gazebo>

  <link name="stabilising_wheel_3">
    <inertial>
      <mass value="1"/>
      <!--origin xyz="0 0 -0.0525" rpy="0 0 0"/-->
      <origin rpy="0 0 0" xyz="0 0 0.0"/>
      <inertia ixx="1" ixy="0" ixz="0" iyy="1" iyz="0" izz="1"/>
    </inertial>
    <visual>
      <origin xyz="0 0 0" rpy="0 0 0"/>
      <geometry>
       <sphere radius="0.020"/>
      </geometry>
    </visual>
    <collision>
      <origin xyz="0 0 0" rpy="0 0 0"/>
      <geometry>
       <sphere radius="0.020"/>
      </geometry>
    </collision>
  </link>
  
  <joint name="stabilising_wheel_base_3" type="continuous">
    <axis xyz="1 1 1"/>
    <parent link="base_link"/>
    <child link="stabilising_wheel_3"/>
    <origin xyz="0.470 .115 0" rpy="-1.5708 0 0"/>
  </joint>

  <gazebo reference="stabilising_wheel_3">
    <material>Gazebo/Black</material>
    <turnGravityOff>false</turnGravityOff>
  </gazebo>

  <link name="stabilising_wheel_4">
    <inertial>
      <mass value="1"/>
      <!--origin xyz="0 0 -0.0525" rpy="0 0 0"/-->
      <origin rpy="0 0 0" xyz="0 0 0.0"/>
      <inertia ixx="1" ixy="0" ixz="0" iyy="1" iyz="0" izz="1"/>
    </inertial>
    <visual>
      <origin xyz="0 0 0" rpy="0 0 0"/>
      <geometry>
        <sphere radius="0.020"/>
      </geometry>
    </visual>
    <collision>
      <origin xyz="0 0 0" rpy="0 0 0"/>
      <geometry>
        <sphere radius="0.020"/>
      </geometry>
    </collision>
  </link>
  
  <joint name="stabilising_wheel_base_4" type="continuous">
    <axis xyz="1 1 1"/>
    <parent link="base_link"/>
    <child link="stabilising_wheel_4"/>
    <origin xyz="0.470 .365 0" rpy="-1.5708 0 0"/>
  </joint>

  <gazebo reference="stabilising_wheel_4">
    <material>Gazebo/Black</material>
    <turnGravityOff>false</turnGravityOff>
  </gazebo>



  <gazebo>
     <plugin name="differential_drive_controller" filename="libgazebo_ros_diff_drive.so">
            <rosDebugLevel>Debug</rosDebugLevel>
            <robotNamespace></robotNamespace>
            <publishWheelTF>false</publishWheelTF>
            <publishWheelJointState>true</publishWheelJointState>
            <alwaysOn>true</alwaysOn>
            <leftJoint>left_diff_wheel_base</leftJoint>
            <rightJoint>right_diff_wheel_base</rightJoint>
            <wheelSeparation>0.3</wheelSeparation>
            <wheelDiameter>0.092</wheelDiameter>
            <wheelTorque>200</wheelTorque>
	    <torque>200</torque>
            <wheelAcceleration>200</wheelAcceleration>
            <commandTopic>cmd_vel</commandTopic>
            <odometryTopic>odom</odometryTopic>
            <odometryFrame>odom</odometryFrame>
            <odometrySource>world</odometrySource>
            <robotBaseFrame>base_link</robotBaseFrame>
            <updateRate>10.0</updateRate>
        </plugin>
  </gazebo>

<!-- SENSOR -->
<gazebo reference="camera_link">
    <sensor type="depth" name="openni_camera_camera">       
        <always_on>1</always_on>
        <visualize>true</visualize>             
        <camera>
            <horizontal_fov>1.047</horizontal_fov>  
            <image>
                <width>640</width>
                <height>480</height>
                <format>R8G8B8</format>
            </image>
            <depth_camera>

            </depth_camera>
            <clip>
                <near>0.1</near>
                <far>100</far>
            </clip>
        </camera>
        <plugin name="camera_controller" filename="libgazebo_ros_openni_kinect.so">
            <alwaysOn>true</alwaysOn>
                <updateRate>50.0</updateRate>
                <cameraName>camera</cameraName>
                <frameName>openni_camera_link</frameName>                   
            <imageTopicName>rgb/image_raw</imageTopicName>
            <depthImageTopicName>depth/image_raw</depthImageTopicName>
            <pointCloudTopicName>depth/points</pointCloudTopicName>
            <cameraInfoTopicName>rgb/camera_info</cameraInfoTopicName>              
            <depthImageCameraInfoTopicName>depth/camera_info</depthImageCameraInfoTopicName>            
            <pointCloudCutoff>0.4</pointCloudCutoff>                
                <hackBaseline>0.07</hackBaseline>
                <distortionK1>0.0</distortionK1>
                <distortionK2>0.0</distortionK2>
                <distortionK3>0.0</distortionK3>
                <distortionT1>0.0</distortionT1>
                <distortionT2>0.0</distortionT2>
            <CxPrime>0.0</CxPrime>
            <Cx>0.0</Cx>
            <Cy>0.0</Cy>
            <focalLength>0.0</focalLength>
            </plugin>
    </sensor>
</gazebo>

<joint name="base_camera_joint" type="fixed">
			<origin xyz="0.37 0.25 1.37" rpy="0 0 0" />
			<parent link="base_link" />
			<child link="camera_link" />
		</joint>

		<link name="camera_link">
			<inertial>
				<mass value="0.01" />
				<origin xyz="0 0 0" />
				<inertia ixx="0.001" ixy="0.0" ixz="0.0" iyy="0.001" iyz="0.0" izz="0.001" />
			</inertial>

			<visual>
				<origin xyz=" 0 0 0 " rpy="0 0 0" />
				<geometry>
					<mesh filename="package://guiabot_description/meshes/kinect.dae"/>
				</geometry>
			</visual>

			<collision>
				<origin xyz="0.0 0.0 0.0" rpy="0 0 0" />
				<geometry>
					<box size="0.0730 .2760 0.0720"/>
				</geometry>
			</collision>
		</link>

		<joint name="camera_depth_joint" type="fixed">
			<origin xyz="0 0.018 0" rpy="0 0 0" />
			<parent link="camera_link" />
			<child link="camera_depth_frame" />
		</joint>

		<link name="camera_depth_frame">
			<inertial>
				<mass value="0.01" />
				<origin xyz="0 0 0" />
				<inertia ixx="0.001" ixy="0.0" ixz="0.0" iyy="0.001" iyz="0.0" izz="0.001" />
			</inertial>
		</link>

		<joint name="camera_depth_optical_joint" type="fixed">
			<origin xyz="0 0 0" rpy="1.5 0 -1.5" />
			<parent link="camera_depth_frame" />
			<child link="camera_depth_optical_frame" />
		</joint>

		<link name="camera_depth_optical_frame">
			<inertial>
				<mass value="0.001" />
				<origin xyz="0 0 0" />
				<inertia ixx="0.0001" ixy="0.0" ixz="0.0" iyy="0.0001" iyz="0.0" izz="0.0001" />
			</inertial>
		</link>

		<joint name="camera_rgb_joint" type="fixed">
			<origin xyz="0 -0.005 0" rpy="0 0 0" />
			<parent link="camera_link" />
			<child link="camera_rgb_frame" />
		</joint>

		<link name="camera_rgb_frame">
			<inertial>
				<mass value="0.001" />
				<origin xyz="0 0 0" />
				<inertia ixx="0.0001" ixy="0.0" ixz="0.0" iyy="0.0001" iyz="0.0" izz="0.0001" />
			</inertial>
		</link>

		<joint name="camera_rgb_optical_joint" type="fixed">
			<origin xyz="0 0 0" rpy="1.5 0 -1.5" />
			<parent link="camera_rgb_frame" />
			<child link="camera_rgb_optical_frame" />
		</joint>

		<link name="camera_rgb_optical_frame">
			<inertial>
				<mass value="0.001" />
				<origin xyz="0 0 0" />
				<inertia ixx="0.0001" ixy="0.0" ixz="0.0" iyy="0.0001" iyz="0.0" izz="0.0001" />
			</inertial>
		</link>

</robot>
