<?xml version="1.0"?>
<robot name="jaco" 
  xmlns:xacro="http://ros.org/wiki/xacro">


<gazebo>
  <plugin name="gazebo_ros_control" filename="libgazebo_ros_control.so">
    <robotNamespace>/jaco</robotNamespace>
  </plugin>
</gazebo>

	<xacro:include filename="$(find jaco_description)/urdf/gazebo/jaco.transmissions.xacro" />

<link name="base_link" >

    <visual>  
      <origin xyz="0 0 0.024" rpy="0 0 0"/>
      <geometry>
        <mesh filename="package://jaco_description/meshes/guaibot.dae" scale="1 1 1"/>
      </geometry>
    </visual>
    <collision>
      <geometry>
        <mesh filename="package://jaco_description/meshes/guaibot.dae" scale="1 1 1"/>
      </geometry>
    </collision>
  </link>

  <joint name="guaibot_interface" type="fixed">
    <origin rpy="0 0 0" xyz="0.629724 0.246784 0.794001"/>
    <parent link="base_link"/>
    <child link="jaco_base_link"/>
  </joint>

<link name="left_diff_wheel">
    <inertial>
      <mass value="50"/>
      <!--origin xyz="0 0 -0.0525" rpy="0 0 0"/-->
      <origin rpy="0 0 0" xyz="0 0 0"/>
      <inertia ixx="1" ixy="0" ixz="0" iyy="1" iyz="0" izz="1"/>
    </inertial>
    <visual>
      <origin xyz="0 0 0" rpy="0 0 0"/>
      <geometry>
        <cylinder length="0.008" radius="0.046"/>
      </geometry>
    </visual>
    <collision>
      <origin xyz="0 0 0" rpy="0 0 0"/>
      <geometry>
        <cylinder length="0.008" radius="0.046"/>
      </geometry>
    </collision>
  </link>
 

  <joint name="left_diff_wheel_base"  type="continuous">
    <axis xyz="0 0 -1"/>
    <parent link="base_link"/>
    <child link="left_diff_wheel"/>
    <origin xyz=".295 .095  0.024" rpy="1.5708 0 0"/>
  </joint>
  <gazebo reference="left_diff_wheel">
    <material>Gazebo/Black</material>
    <turnGravityOff>false</turnGravityOff>
  </gazebo>

  <link name="right_diff_wheel">
    <inertial>
      <mass value="50"/>
      <!--origin xyz="0 0 -0.0525" rpy="0 0 0"/-->
      <origin rpy="0 0 0" xyz="0 0 0.0"/>
      <inertia ixx="1" ixy="0" ixz="0" iyy="1" iyz="0" izz="1"/>
    </inertial>
    <visual>
      <origin xyz="0 0 0" rpy="0 0 0"/>
      <geometry>
        <cylinder length="0.008" radius="0.046"/>
      </geometry>
    </visual>
    <collision>
      <origin xyz="0 0 0" rpy="0 0 0"/>
      <geometry>
        <cylinder length="0.008" radius="0.046"/>
      </geometry>
    </collision>
  </link>
  
  <joint name="right_diff_wheel_base"  type="continuous">
    <axis xyz="0 0 -1"/>
   <parent link="base_link"/>
    <child link="right_diff_wheel"/>
    <origin xyz=".295 .395  0.024" rpy="-1.5708 0 0"/>
  </joint>

    <gazebo reference="right_diff_wheel">
    <material>Gazebo/Black</material>
    <turnGravityOff>false</turnGravityOff>
  </gazebo>

  <link name="stabilising_wheel_1">
    <inertial>
      <mass value="1"/>
      <!--origin xyz="0 0 -0.0525" rpy="0 0 0"/-->
      <origin rpy="0 0 0" xyz="0 0 0.0"/>
      <inertia ixx="1" ixy="0" ixz="0" iyy="1" iyz="0" izz="1"/>
    </inertial>
    <visual>
      <origin xyz="0 0 0" rpy="0 0 0"/>
      <geometry>
        <sphere radius="0.020"/>
      </geometry>
    </visual>
    <collision>
      <origin xyz="0 0 0" rpy="0 0 0"/>
      <geometry>
        <sphere radius="0.020"/>
      </geometry>
    </collision>
  </link>
  
  <joint name="stabilising_wheel_base_1" type="continuous">
    <parent link="base_link"/>
    <child link="stabilising_wheel_1"/>
    <origin xyz="0.120 .115 0" rpy="-1.5708 0 0"/>
  </joint>

  <gazebo reference="stabilising_wheel_1">
    <material>Gazebo/Black</material>
    <turnGravityOff>false</turnGravityOff>
  </gazebo>

  <link name="stabilising_wheel_2">
    <inertial>
      <mass value="1"/>
      <!--origin xyz="0 0 -0.0525" rpy="0 0 0"/-->
      <origin rpy="0 0 0" xyz="0 0 0.0"/>
      <inertia ixx="1" ixy="0" ixz="0" iyy="1" iyz="0" izz="1"/>
    </inertial>
    <visual>
      <origin xyz="0 0 0" rpy="0 0 0"/>
      <geometry>
        <sphere radius="0.020"/>
      </geometry>
    </visual>
    <collision>
      <origin xyz="0 0 0" rpy="0 0 0"/>
      <geometry>
        <sphere radius="0.020"/>
      </geometry>
    </collision>
  </link>
  
  <joint name="stabilising_wheel_base_2" type="continuous">
    <axis xyz="1 1 1"/>
    <parent link="base_link"/>
    <child link="stabilising_wheel_2"/>
    <origin xyz="0.120 .365 0" rpy="-1.5708 0 0"/>
  </joint>

  <gazebo reference="stabilising_wheel_2">
    <material>Gazebo/Black</material>
    <turnGravityOff>false</turnGravityOff>
  </gazebo>

  <link name="stabilising_wheel_3">
    <inertial>
      <mass value="1"/>
      <!--origin xyz="0 0 -0.0525" rpy="0 0 0"/-->
      <origin rpy="0 0 0" xyz="0 0 0.0"/>
      <inertia ixx="1" ixy="0" ixz="0" iyy="1" iyz="0" izz="1"/>
    </inertial>
    <visual>
      <origin xyz="0 0 0" rpy="0 0 0"/>
      <geometry>
       <sphere radius="0.020"/>
      </geometry>
    </visual>
    <collision>
      <origin xyz="0 0 0" rpy="0 0 0"/>
      <geometry>
       <sphere radius="0.020"/>
      </geometry>
    </collision>
  </link>
  
  <joint name="stabilising_wheel_base_3" type="continuous">
    <axis xyz="1 1 1"/>
    <parent link="base_link"/>
    <child link="stabilising_wheel_3"/>
    <origin xyz="0.470 .115 0" rpy="-1.5708 0 0"/>
  </joint>

  <gazebo reference="stabilising_wheel_3">
    <material>Gazebo/Black</material>
    <turnGravityOff>false</turnGravityOff>
  </gazebo>

  <link name="stabilising_wheel_4">
    <inertial>
      <mass value="1"/>
      <!--origin xyz="0 0 -0.0525" rpy="0 0 0"/-->
      <origin rpy="0 0 0" xyz="0 0 0.0"/>
      <inertia ixx="1" ixy="0" ixz="0" iyy="1" iyz="0" izz="1"/>
    </inertial>
    <visual>
      <origin xyz="0 0 0" rpy="0 0 0"/>
      <geometry>
        <sphere radius="0.020"/>
      </geometry>
    </visual>
    <collision>
      <origin xyz="0 0 0" rpy="0 0 0"/>
      <geometry>
        <sphere radius="0.020"/>
      </geometry>
    </collision>
  </link>
  
  <joint name="stabilising_wheel_base_4" type="continuous">
    <axis xyz="1 1 1"/>
    <parent link="base_link"/>
    <child link="stabilising_wheel_4"/>
    <origin xyz="0.470 .365 0" rpy="-1.5708 0 0"/>
  </joint>

  <gazebo reference="stabilising_wheel_4">
    <material>Gazebo/Black</material>
    <turnGravityOff>false</turnGravityOff>
  </gazebo>

  <material name="JacoGrey">
    <color rgba="0.2 0.2 0.9 1.0"/>
  </material>

  <link name="jaco_base_link" type="fixed">
    <inertial>
      <mass value="1"/>
      <!--origin xyz="0 0 -0.0525" rpy="0 0 0"/-->
      <origin rpy="0 0 0" xyz="0 0 0.0"/>
      <inertia ixx="1" ixy="0" ixz="0" iyy="1" iyz="0" izz="1"/>
    </inertial>
    <visual>
      <material name="JacoGrey"/>
      <!--origin xyz="0 0 -0.0525" rpy="0 0 0"/-->
      <geometry>
        <mesh filename="package://jaco_description/meshes/joint_1.stl" scale="0.001 0.001 0.001"/>
      </geometry>
    </visual>
    <collision>
      <!--origin xyz="0 0 -0.0525" rpy="0 0 0"/-->
      <geometry>
        <mesh filename="package://jaco_description/meshes/joint_1.stl" scale="0.001 0.001 0.001"/>
      </geometry>
    </collision>
   <parent link="base_link"/>
    <child link="jaco_link_1"/>
  </link>

  <gazebo reference="jaco_base_link">
    <material>Gazebo/Yellow</material>
    <turnGravityOff>false</turnGravityOff>
  </gazebo>

  <joint name="jaco_joint_1" type="revolute">
    <!--origin xyz="0 0 0.2102" rpy="0 0 0"/-->
    <origin rpy="0 0 0" xyz="0 0 0.2725"/>
    <axis rpy="0 0 0" xyz="0 0 -1"/>
    <parent link="jaco_base_link"/>
    <child link="jaco_link_1"/>
    <limit effort="30" lower="-3.14159265359" upper="3.14159265359" velocity="5"/>
  </joint>

  <link name="jaco_link_1">
    <inertial>
      <mass value="1"/>
      <inertia ixx="1" ixy="0" ixz="0" iyy="1" iyz="0" izz="1"/>
      <origin/>
    </inertial>
    <visual>
      <material name="JacoGrey"/>
      <origin rpy="0 0 -1.570796327" xyz="0 0 -0.12"/>
      <geometry>
        <mesh filename="package://jaco_description/meshes/joint_2.stl" scale="0.001 0.001 0.001"/>
      </geometry>
    </visual>
    <collision>
      <origin rpy="0 0 -1.570796327" xyz="0 0 -0.12"/>
      <geometry>
        <mesh filename="package://jaco_description/meshes/joint_2.stl" scale="0.001 0.001 0.001"/>
      </geometry>
    </collision>
  </link>
  <gazebo reference="jaco_link_1">
    <material>Gazebo/Red</material>
    <turnGravityOff>false</turnGravityOff>
  </gazebo>
  <joint name="jaco_joint_2" type="revolute">
    <origin rpy="-1.570796327 0 0" xyz="0 0 0"/>
    <axis xyz="0 0 1"/>
    <parent link="jaco_link_1"/>
    <child link="jaco_link_2"/>
    <limit effort="30" lower="-3.14159265359" upper="3.14159265359" velocity="5"/>
  </joint>
  <link name="jaco_link_2">
    <inertial>
      <mass value="1"/>
      <inertia ixx="1" ixy="0" ixz="0" iyy="1" iyz="0" izz="1"/>
      <origin/>
    </inertial>
    <visual>
      <material name="JacoGrey"/>
      <origin rpy="0 1.570796327 0" xyz="0 0 0.015"/>
      <geometry>
        <mesh filename="package://jaco_description/meshes/joint_3.stl" scale="0.001 0.001 0.001"/>
      </geometry>
    </visual>
    <collision>
      <origin rpy="0 1.570796327 0" xyz="0 0 0.015"/>
      <geometry>
        <mesh filename="package://jaco_description/meshes/joint_3.stl" scale="0.001 0.001 0.001"/>
      </geometry>
    </collision>
  </link>
  <gazebo reference="jaco_link_2">
    <material>Gazebo/Blue</material>
    <turnGravityOff>false</turnGravityOff>
  </gazebo>
  <joint name="jaco_joint_3" type="revolute">
    <origin rpy="0 0 0" xyz="0.4100 0 0.012"/>
    <axis xyz="0 0 -1"/>
    <parent link="jaco_link_2"/>
    <child link="jaco_link_3"/>
    <limit effort="30" lower="-3.14159265359" upper="3.14159265359" velocity="5"/>
  </joint>
  <link name="jaco_link_3">
    <inertial>
      <mass value="1"/>
      <inertia ixx="1" ixy="0" ixz="0" iyy="1" iyz="0" izz="1"/>
      <origin/>
    </inertial>
    <visual>
      <material name="JacoGrey"/>
      <origin rpy="0 1.570796327 1.570796327" xyz="0 0 -0.012"/>
      <geometry>
        <mesh filename="package://jaco_description/meshes/joint_4.stl" scale="1.000 1.000 1.000"/>
      </geometry>
    </visual>
    <collision>
      <origin rpy="0 1.570796327 1.570796327" xyz="0 0 -0.012"/>
      <geometry>
        <mesh filename="package://jaco_description/meshes/joint_4.stl" scale="1.000 1.000 1.000"/>
      </geometry>
    </collision>
  </link>
  <gazebo reference="jaco_link_3">
    <material>Gazebo/Red</material>
    <turnGravityOff>false</turnGravityOff>
  </gazebo>
  <joint name="jaco_joint_4" type="revolute">
    <origin rpy="-1.570796327 0 0" xyz="0 0.24927682300748782 0 "/>
    <axis xyz="0 0 -1"/>
    <parent link="jaco_link_3"/>
    <child link="jaco_link_4"/>
    <limit effort="30" lower="-3.14159265359" upper="3.14159265359" velocity="5"/>
  </joint>
  <link name="jaco_link_4">
    <inertial>
      <mass value="1"/>
      <inertia ixx="1" ixy="0" ixz="0" iyy="1" iyz="0" izz="1"/>
      <origin/>
    </inertial>
    <visual>
      <material name="JacoGrey"/>
      <origin rpy="0 0 -1.570796327" xyz="0 0 -0.042276823"/>
      <geometry>
        <mesh filename="package://jaco_description/meshes/joint_5.stl" scale="0.001 0.001 0.001"/>
      </geometry>
    </visual>
    <collision>
      <origin rpy="0 0 -1.570796327" xyz="0 0 -0.042276823"/>
      <geometry>
        <mesh filename="package://jaco_description/meshes/joint_5.stl" scale="0.001 0.001 0.001"/>
      </geometry>
    </collision>
  </link>
  <gazebo reference="jaco_link_4">
    <material>Gazebo/Blue</material>
    <turnGravityOff>false</turnGravityOff>
  </gazebo>
  <joint name="jaco_joint_5" type="revolute">
    <origin rpy="0.959931089 0 0" xyz="0 -0.069262292 0.048497979"/>
    <axis xyz="0 0 -1"/>
    <parent link="jaco_link_4"/>
    <child link="jaco_link_5"/>
    <limit effort="30" lower="-3.14159265359" upper="3.14159265359" velocity="5"/>
  </joint>
  <link name="jaco_link_5">
    <inertial>
      <mass value="1.0"/>
      <inertia ixx="1" ixy="0" ixz="0" iyy="1" iyz="0" izz="1"/>
      <origin/>
    </inertial>
    <visual>
      <material name="JacoGrey"/>
      <origin rpy="0 -0.959931089 1.570796327" xyz="0 0 -0.042276823"/>
      <geometry>
        <mesh filename="package://jaco_description/meshes/joint_6.stl" scale="0.001 0.001 0.001"/>
      </geometry>
    </visual>
    <collision>
      <origin rpy="0 -0.959931089 1.570796327" xyz="0 0 -0.042276823"/>
      <geometry>
        <mesh filename="package://jaco_description/meshes/joint_6.stl" scale="0.001 0.001 0.001"/>
      </geometry>
    </collision>
  </link>
  <gazebo reference="jaco_link_5">
    <material>Gazebo/Red</material>
    <turnGravityOff>false</turnGravityOff>
  </gazebo>
  <joint name="jaco_joint_6" type="revolute">
    <!--origin xyz="0 -0.186174274 0.13036063" rpy="0.959931089 0 0"/-->
    <origin rpy="-0.959931089 0 3.1415926535897931" xyz="0 -0.186174274 0.13036063"/>
    <!--<origin xyz="0 0 0" rpy="0 0 -3.14"/>-->
    <axis xyz="0 0 -1"/>
    <parent link="jaco_link_5"/>
    <child link="jaco_link_6"/>
    <limit effort="30" lower="-3.14159265359" upper="3.14159265359" velocity="5"/>
  </joint>
  <link name="jaco_link_6">
    <inertial>
      <mass value="0.3"/>
      <inertia ixx="1" ixy="0" ixz="0" iyy="1" iyz="0" izz="1"/>
      <origin/>
    </inertial>
    <visual>
      <material name="JacoGrey"/>
      <origin rpy="0 0 -3.1415926535897931" xyz="0 0 -0.1850"/>
      <!--<origin xyz="0 0 -0.1850" rpy="0 0 0"/>      -->
      <geometry>
        <mesh filename="package://jaco_description/meshes/hand_with_noFinger.stl" scale="0.001 0.001 0.001"/>
      </geometry>
    </visual>
    <collision>
      <origin rpy="0 0 -3.1415926535897931" xyz="0 0 -0.1850"/>
      <!--<origin xyz="0 0 -0.1850" rpy="0 0 0"/>-->
      <geometry>
        <mesh filename="package://jaco_description/meshes/hand_with_noFinger.stl" scale="0.001 0.001 0.001"/>
      </geometry>
    </collision>
  </link>
  <gazebo reference="jaco_link_6">
    <material>Gazebo/Blue</material>
    <turnGravityOff>false</turnGravityOff>
  </gazebo>
  <joint name="jaco_gripper_tool_frame_joint" type="fixed">
    <parent link="jaco_link_6"/>
    <child link="jaco_gripper_tool_frame"/>
    <origin rpy="0.23 -1.570796327 1.570796327" xyz="0 0 -0.08"/>
  </joint>
  <link name="jaco_gripper_tool_frame">
    <!-- This is the coordinate system of the tool (this is the position
         used in IK etc., relative to the base frame); there is no actual
         arm part attached to this link -->
  </link>
  <joint name="jaco_finger_joint_1" type="revolute">
    <!--origin xyz="-0.036 -0.021 -0.07" rpy="0 0 0"/-->
    <!-- changed becuase it look funny in simulation-->
    <origin rpy="0 0 3.14159265359" xyz="0.036 -0.021 -0.09"/>
    <axis xyz="0 1 0"/>
    <parent link="jaco_link_6"/>
    <child link="jaco_finger_link_1"/>
    <limit effort="30" lower="0.004" upper="1.044" velocity="5"/>
  </joint>
  <link name="jaco_finger_link_1">
    <inertial>
      <mass value="0.05"/>
      <inertia ixx="1" ixy="0" ixz="0" iyy="1" iyz="0" izz="1"/>
      <origin/>
    </inertial>
    <visual>
      <origin rpy="0 0 0" xyz="0 0 0"/>
      <geometry>
        <mesh filename="package://jaco_description/meshes/finger.stl" scale="1 1 1"/>
      </geometry>
    </visual>
    <collision>
      <origin rpy="0 0 0" xyz="0 0 0"/>
      <geometry>
        <mesh filename="package://jaco_description/meshes/finger.stl" scale="1 1 1"/>
      </geometry>
    </collision>
  </link>
  <gazebo reference="jaco_finger_link_1">
    <material>Gazebo/Blue</material>
    <turnGravityOff>false</turnGravityOff>
  </gazebo>
  <joint name="jaco_finger_joint_2" type="revolute">
    <!--origin xyz="-0.036 0.021 -0.07" rpy="0 0 0"/-->
    <origin rpy="0 0 3.37159265359" xyz="0.036 0.021 -0.09"/>
    <axis xyz="0 1 0"/>
    <parent link="jaco_link_6"/>
    <child link="jaco_finger_link_2"/>
    <limit effort="30" lower="0.004" upper="1.044" velocity="5"/>
  </joint>
  <link name="jaco_finger_link_2">
    <inertial>
      <mass value="0.05"/>
      <inertia ixx="1" ixy="0" ixz="0" iyy="1" iyz="0" izz="1"/>
      <origin/>
    </inertial>
    <visual>
      <origin rpy="0 0 0" xyz="0 0 0"/>
      <geometry>
        <mesh filename="package://jaco_description/meshes/finger.stl" scale="1 1 1"/>
      </geometry>
    </visual>
    <collision>
      <origin rpy="0 0 0" xyz="0 0 0"/>
      <geometry>
        <mesh filename="package://jaco_description/meshes/finger.stl" scale="1 1 1"/>
      </geometry>
    </collision>
  </link>
  <gazebo reference="jaco_finger_link_2">
    <material>Gazebo/Blue</material>
    <turnGravityOff>false</turnGravityOff>
  </gazebo>
  <joint name="jaco_finger_joint_3" type="revolute">
    <!--origin xyz="0.036 -0 -0.07" rpy="0 0 3.14"/-->
    <origin rpy="0 0 0.23" xyz="-0.036 -0 -0.09"/>
    <axis xyz="0 1 0"/>
    <parent link="jaco_link_6"/>
    <child link="jaco_finger_link_3"/>
    <limit effort="30" lower="0.004" upper="1.044" velocity="5"/>
  </joint>
  <link name="jaco_finger_link_3">
    <inertial>
      <mass value="0.05"/>
      <inertia ixx="1" ixy="0" ixz="0" iyy="1" iyz="0" izz="1"/>
      <origin/>
    </inertial>
    <visual>
      <origin rpy="0 0 0" xyz="0 0 0"/>
      <geometry>
        <mesh filename="package://jaco_description/meshes/finger.stl" scale="1 1 1"/>
      </geometry>
    </visual>
    <collision>
      <origin rpy="0 0 0" xyz="0 0 0"/>
      <geometry>
        <mesh filename="package://jaco_description/meshes/finger.stl" scale="1 1 1"/>
      </geometry>
    </collision>
  </link>
  <gazebo reference="jaco_finger_link_3">
    <material>Gazebo/Blue</material>
    <turnGravityOff>false</turnGravityOff>
  </gazebo>

  <gazebo>
     <plugin name="differential_drive_controller" filename="libgazebo_ros_diff_drive.so">
            <rosDebugLevel>Debug</rosDebugLevel>
            <robotNamespace></robotNamespace>
            <publishWheelTF>false</publishWheelTF>
            <publishWheelJointState>true</publishWheelJointState>
            <alwaysOn>true</alwaysOn>
            <leftJoint>left_diff_wheel_base</leftJoint>
            <rightJoint>right_diff_wheel_base</rightJoint>
            <wheelSeparation>0.3</wheelSeparation>
            <wheelDiameter>0.092</wheelDiameter>
            <wheelTorque>200</wheelTorque>
	    <torque>200</torque>
            <wheelAcceleration>200</wheelAcceleration>
            <commandTopic>cmd_vel</commandTopic>
            <odometryTopic>odom</odometryTopic>
            <odometryFrame>odom</odometryFrame>
            <odometrySource>world</odometrySource>
            <robotBaseFrame>base_link</robotBaseFrame>
            <updateRate>10.0</updateRate>
        </plugin>
  </gazebo>

<!-- SENSOR -->
<gazebo reference="camera_link">
    <sensor type="depth" name="openni_camera_camera">       
        <always_on>1</always_on>
        <visualize>true</visualize>             
        <camera>
            <horizontal_fov>1.047</horizontal_fov>  
            <image>
                <width>640</width>
                <height>480</height>
                <format>R8G8B8</format>
            </image>
            <depth_camera>

            </depth_camera>
            <clip>
                <near>0.1</near>
                <far>100</far>
            </clip>
        </camera>
        <plugin name="camera_controller" filename="libgazebo_ros_openni_kinect.so">
            <alwaysOn>true</alwaysOn>
                <updateRate>50.0</updateRate>
                <cameraName>camera</cameraName>
                <frameName>openni_camera_link</frameName>                   
            <imageTopicName>rgb/image_raw</imageTopicName>
            <depthImageTopicName>depth/image_raw</depthImageTopicName>
            <pointCloudTopicName>depth/points</pointCloudTopicName>
            <cameraInfoTopicName>rgb/camera_info</cameraInfoTopicName>              
            <depthImageCameraInfoTopicName>depth/camera_info</depthImageCameraInfoTopicName>            
            <pointCloudCutoff>0.4</pointCloudCutoff>                
                <hackBaseline>0.07</hackBaseline>
                <distortionK1>0.0</distortionK1>
                <distortionK2>0.0</distortionK2>
                <distortionK3>0.0</distortionK3>
                <distortionT1>0.0</distortionT1>
                <distortionT2>0.0</distortionT2>
            <CxPrime>0.0</CxPrime>
            <Cx>0.0</Cx>
            <Cy>0.0</Cy>
            <focalLength>0.0</focalLength>
            </plugin>
    </sensor>
</gazebo>

<joint name="base_camera_joint" type="fixed">
			<origin xyz="0.37 0.25 1.37" rpy="0 0 0" />
			<parent link="base_link" />
			<child link="camera_link" />
		</joint>

		<link name="camera_link">
			<inertial>
				<mass value="0.01" />
				<origin xyz="0 0 0" />
				<inertia ixx="0.001" ixy="0.0" ixz="0.0" iyy="0.001" iyz="0.0" izz="0.001" />
			</inertial>

			<visual>
				<origin xyz=" 0 0 0 " rpy="0 0 0" />
				<geometry>
					<mesh filename="package://jaco_description/meshes/kinect.dae"/>
				</geometry>
			</visual>

			<collision>
				<origin xyz="0.0 0.0 0.0" rpy="0 0 0" />
				<geometry>
					<box size="0.0730 .2760 0.0720"/>
				</geometry>
			</collision>
		</link>

		<joint name="camera_depth_joint" type="fixed">
			<origin xyz="0 0.018 0" rpy="0 0 0" />
			<parent link="camera_link" />
			<child link="camera_depth_frame" />
		</joint>

		<link name="camera_depth_frame">
			<inertial>
				<mass value="0.01" />
				<origin xyz="0 0 0" />
				<inertia ixx="0.001" ixy="0.0" ixz="0.0" iyy="0.001" iyz="0.0" izz="0.001" />
			</inertial>
		</link>

		<joint name="camera_depth_optical_joint" type="fixed">
			<origin xyz="0 0 0" rpy="${-M_PI/2} 0 ${-M_PI/2}" />
			<parent link="camera_depth_frame" />
			<child link="camera_depth_optical_frame" />
		</joint>

		<link name="camera_depth_optical_frame">
			<inertial>
				<mass value="0.001" />
				<origin xyz="0 0 0" />
				<inertia ixx="0.0001" ixy="0.0" ixz="0.0" iyy="0.0001" iyz="0.0" izz="0.0001" />
			</inertial>
		</link>

		<joint name="camera_rgb_joint" type="fixed">
			<origin xyz="0 -0.005 0" rpy="0 0 0" />
			<parent link="camera_link" />
			<child link="camera_rgb_frame" />
		</joint>

		<link name="camera_rgb_frame">
			<inertial>
				<mass value="0.001" />
				<origin xyz="0 0 0" />
				<inertia ixx="0.0001" ixy="0.0" ixz="0.0" iyy="0.0001" iyz="0.0" izz="0.0001" />
			</inertial>
		</link>

		<joint name="camera_rgb_optical_joint" type="fixed">
			<origin xyz="0 0 0" rpy="${-M_PI/2} 0 ${-M_PI/2}" />
			<parent link="camera_rgb_frame" />
			<child link="camera_rgb_optical_frame" />
		</joint>

		<link name="camera_rgb_optical_frame">
			<inertial>
				<mass value="0.001" />
				<origin xyz="0 0 0" />
				<inertia ixx="0.0001" ixy="0.0" ixz="0.0" iyy="0.0001" iyz="0.0" izz="0.0001" />
			</inertial>
		</link>

</robot>
